Workbook

Sheet Sales_Dataset
A1: Order_ID | B1: Order_Date | C1: Customer_ID | D1: Customer_Name | E1: Age | F1: Gender | G1: City | H1: Product | I1: Category | J1: Quantity | K1: Unit_Price | L1: Total_Sales | N1: Q1 | O1: Q3 | P1: IQR | Q1: Lower Limit | R1: Upper Limit | T1: Q1 | U1: Q3 | V1: IQR | W1: LowerLimit | X1: Upper Limit | Z1: Q1 | AA1: Q3 | AB1: IQR | AC1: Lower Limit | AD1: Upper Limit | AF1: Q1 | AG1: Q3 | AH1: IQR | AI1: Lower Limit | AJ1: Upper Limit
A2: ORD100002 | B2: 2025-02-25 | C2: CUST5529 | D2: Customer_227 | E2: 30 | F2: Female | G2: Bengaluru | H2: Rice | I2: Grocery | J2: 7 | K2: 2829.77 | L2: 19808.39 | N2: =_xlfn.QUARTILE.INC(E:E,1) -> 30 | O2: =_xlfn.QUARTILE.INC(E:E,3) -> 54 | P2: =O2-N2 -> 24 | Q2: =N2-(1.5*P2) -> -6 | R2: =O2+(1.5*P2) -> 90 | T2: =_xlfn.QUARTILE.INC(J:J,1) -> 3 | U2: =_xlfn.QUARTILE.INC(J:J,3) -> 8 | V2: =U2-T2 -> 5 | W2: =T2-(1.5*V2) -> -4.5 | X2: =U2+(1.5*V2) -> 15.5 | Z2: =_xlfn.QUARTILE.INC(K:K,1) -> 13895.722 | AA2: =_xlfn.QUARTILE.INC(K:K,3) -> 37512.382 | AB2: =AA2-Z2 -> 23616.66 | AC2: =Z2-(1.5*AB2) -> -21529.267 | AD2: =AA2+(1.5*AB2) -> 72937.372 | AF2: =_xlfn.QUARTILE.INC(L:L,1) -> 47066.632 | AG2: =_xlfn.QUARTILE.INC(L:L,3) -> 203722.88 | AH2: =AG2-AF2 -> 156656.25 | AI2: =AF2-(1.5*AH2) -> -187917.74 | AJ2: =AG2+(1.5*AH2) -> 438707.26 | AK2: =COUNTIF(L2:L1001,">"&AJ2)+COUNTIF(L2:L1001,"<"&AI2) -> 19
A3: ORD100003 | B3: 2025-10-14 | C3: CUST3127 | D3: Customer_182 | E3: 63 | F3: Male | G3: Bengaluru | H3: Book | I3: Education | J3: 5 | K3: 27906.16 | L3: 139530.8
A4: ORD100004 | B4: 2025-05-13 | C4: CUST8887 | D4: Customer_487 | E4: 62 | F4: Female | G4: Bengaluru | H4: Book | I4: Education | J4: 8 | K4: 37491.06 | L4: 299928.48
A5: ORD100005 | B5: 2025-12-02 | C5: CUST2515 | D5: Customer_470 | E5: 65 | F5: Female | G5: Kolkata | H5: Mobile | I5: Electronics | J5: 9 | K5: 28541.36 | L5: 256872.24
A6: ORD100006 | B6: 2025-11-20 | C6: CUST4796 | D6: Customer_380 | E6: 44 | F6: Male | G6: Bengaluru | H6: Rice | I6: Grocery | J6: 10 | K6: 14036.59 | L6: 140365.9
A7: ORD100007 | B7: 2025-12-31 | C7: CUST3952 | D7: Customer_71 | E7: 40 | F7: Female | G7: Hyderabad | H7: Laptop | I7: Electronics | J7: 9 | K7: 35947.47 | L7: 323527.23
A8: ORD100008 | B8: 2025-10-14 | C8: CUST1758 | D8: Customer_335 | E8: 61 | F8: Male | G8: Patna | H8: Mobile | I8: Electronics | J8: 6 | K8: 49997.53 | L8: 299985.18
A9: ORD100009 | B9: 2025-12-05 | C9: CUST9622 | D9: Customer_224 | E9: 35 | F9: Male | G9: Kolkata | H9: Laptop | I9: Electronics | J9: 3 | K9: 9488.83 | L9: 28466.49
A10: ORD100010 | B10: 2025-11-21 | C10: CUST9770 | D10: Customer_494 | E10: 41 | F10: Female | G10: Mumbai | H10: Book | I10: Education | J10: 6 | K10: 19488.23 | L10: 116929.38
A11: ORD100011 | B11: 2025-04-16 | C11: CUST1312 | D11: Customer_40 | E11: 30 | F11: Male | G11: Kolkata | H11: Mobile | I11: Electronics | J11: 8 | K11: 18024.34 | L11: 144194.72
A12: ORD100012 | B12: 2025-05-05 | C12: CUST9642 | D12: Customer_162 | E12: 51 | F12: Male | G12: Delhi | H12: Shoes | I12: Fashion | J12: 3 | K12: 14151.42 | L12: 42454.26
A13: ORD100013 | B13: 2025-05-02 | C13: CUST3228 | D13: Customer_209 | E13: 55 | F13: Female | G13: Patna | H13: Chair | I13: Furniture | J13: 6 | K13: 47175.43 | L13: 283052.58
A14: ORD100014 | B14: 2025-05-06 | C14: CUST1038 | D14: Customer_454 | E14: 32 | F14: Male | G14: Patna | H14: Rice | I14: Grocery | J14: 5 | K14: 7413.68 | L14: 37068.4
... A49: ORD100049 | B49: 2025-10-25 | C49: CUST2705 | D49: Customer_117 | E49: 55 | F49: Male | G49: Kolkata | H49: Mobile | I49: Electronics | J49: 5 | K49: 24854.05 | L49: 124270.25
A50: ORD100050 | B50: 2025-10-03 | C50: CUST5523 | D50: Customer_432 | F50: Male | G50: Pune | H50: Chair | I50: Furniture | J50: 9 | K50: 30834.87 | L50: 277513.83
A51: ORD100051 | B51: 2025-02-27 | C51: CUST1557 | D51: Customer_87 | E51: 39 | F51: Female | G51: Mumbai | H51: Chair | I51: Furniture | J51: 6 | K51: 20561.97 | L51: 123371.82
A52: ORD100052 | B52: 2025-09-09 | C52: CUST2062 | D52: Customer_254 | E52: 58 | F52: Male | G52: Patna | H52: Book | I52: Education | J52: 10 | K52: 49367.75 | L52: 493677.5
A53: ORD100053 | B53: 2025-06-08 | C53: CUST9203 | D53: Customer_70 | E53: 33 | F53: Male | G53: Delhi | H53: Laptop | I53: Electronics | J53: 6 | K53: 4656.1 | L53: 27936.6
A54: ORD100054 | B54: 2025-07-07 | C54: CUST8053 | D54: Customer_408 | E54: 58 | F54: Male | G54: Delhi | H54: Rice | I54: Grocery | J54: 7 | K54: 42345.82 | L54: 296420.74
A55: ORD100055 | B55: 2025-04-16 | C55: CUST1017 | D55: Customer_387 | E55: 42 | F55: Female | G55: Pune | H55: Shoes | I55: Fashion | J55: 7 | K55: 37747.24 | L55: 264230.68
A56: ORD100056 | B56: 2025-11-16 | C56: CUST2690 | D56: Customer_11 | E56: 26 | F56: Male | G56: Delhi | H56: Book | I56: Education | J56: 2 | K56: 33304.17 | L56: 66608.34
A57: ORD100057 | B57: 2025-12-07 | C57: CUST2791 | D57: Customer_20 | E57: 58 | F57: Female | G57: Bengaluru | H57: Laptop | I57: Electronics | J57: 6 | K57: 41157.44 | L57: 246944.64
A58: ORD100058 | B58: 2025-03-12 | C58: CUST4496 | D58: Customer_53 | E58: 18 | F58: Female | G58: Bengaluru | H58: Chair | I58: Furniture | J58: 7 | K58: 47669.63 | L58: 333687.41
A59: ORD100059 | B59: 2025-12-12 | C59: CUST8811 | D59: Customer_115 | E59: 50 | F59: Female | G59: Bengaluru | H59: Chair | I59: Furniture | J59: 1 | K59: 44708.5 | L59: 44708.5
A60: ORD100060 | B60: 2025-01-15 | C60: CUST2411 | D60: Customer_292 | E60: 47 | F60: Female | G60: Mumbai | H60: Mobile | I60: Electronics | J60: 5 | K60: 36809.08 | L60: 184045.4
A61: ORD100061 | B61: 2025-11-08 | C61: CUST2350 | D61: Customer_205 | E61: 46 | F61: Male | G61: Pune | H61: Mobile | I61: Electronics | J61: 4 | K61: 25292.97 | L61: 101171.88
A62: ORD100062 | B62: 2025-07-06 | C62: CUST9745 | D62: Customer_48 | E62: 27 | F62: Male | G62: Mumbai | H62: Shoes | I62: Fashion | J62: 1 | K62: 29263.26 | L62: 29263.26
... A74: ORD100074 | B74: 2025-12-04 | C74: CUST7587 | D74: Customer_223 | E74: 27 | F74: Male | G74: Pune | H74: Laptop | I74: Electronics | J74: 9 | K74: 45419.62 | L74: 408776.58
A75: ORD100075 | B75: 2025-03-30 | C75: CUST2157 | D75: Customer_31 | E75: 58 | F75: Male | H75: Mobile | I75: Electronics | J75: 4 | K75: 21599.26 | L75: 86397.04
A76: ORD100076 | B76: 2025-12-30 | C76: CUST8430 | D76: Customer_277 | E76: 45 | F76: Male | G76: Gaya | H76: Laptop | I76: Electronics | J76: 2 | K76: 8883.45 | L76: 17766.9
A77: ORD100077 | B77: 2025-12-27 | C77: CUST1956 | D77: Customer_317 | E77: 22 | F77: Female | G77: Bengaluru | H77: Shoes | I77: Fashion | J77: 9 | K77: 12290.45 | L77: 110614.05
A78: ORD100078 | B78: 2025-04-14 | C78: CUST9846 | D78: Customer_298 | E78: 58 | F78: Female | G78: Patna | H78: Book | I78: Education | J78: 6 | K78: 10784.64 | L78: 64707.84
A79: ORD100079 | B79: 2026-01-01 | C79: CUST4706 | D79: Customer_34 | E79: 62 | F79: Female | G79: Delhi | H79: Rice | I79: Grocery | J79: 1 | K79: 35862.34 | L79: 35862.34
A80: ORD100080 | B80: 2025-08-21 | C80: CUST5607 | D80: Customer_265 | E80: 61 | F80: Female | G80: Gaya | H80: Rice | I80: Grocery | J80: 1 | K80: 13129.64 | L80: 13129.64
A81: ORD100081 | B81: 2025-03-05 | C81: CUST8211 | D81: Customer_62 | E81: 19 | F81: Female | G81: Gaya | H81: Chair | I81: Furniture | J81: 9 | K81: 45747.37 | L81: 411726.33
A82: ORD100082 | B82: 2025-09-01 | C82: CUST5367 | D82: Customer_499 | E82: 25 | F82: Female | G82: Hyderabad | H82: Book | I82: Education | J82: 6 | K82: 5849.89 | L82: 35099.34
A83: ORD100083 | B83: 2025-01-06 | C83: CUST8346 | D83: Customer_384 | E83: 30 | F83: Male | G83: Hyderabad | H83: Laptop | I83: Electronics | J83: 9 | K83: 48845.5 | L83: 439609.5
A84: ORD100084 | B84: 2025-10-24 | C84: CUST7484 | D84: Customer_478 | E84: 36 | F84: Male | G84: Gaya | H84: Book | I84: Education | J84: 9 | K84: 24828.05 | L84: 223452.45
A85: ORD100085 | B85: 2025-03-07 | C85: CUST7911 | D85: Customer_7 | E85: 59 | F85: Male | G85: Delhi | H85: Mobile | I85: Electronics | J85: 8 | K85: 17841.4 | L85: 142731.2
...

Sheet Data_Quality_Report
A1: Issue | B1: Column | C1: Count | D1: Action/Observation
A2: Missing Values | B2: Age | C2: 20 | D2: To be handled during data cleaning
A3: Missing Values | B3: City | C3: 13 | D3: To be handled during data cleaning
A4: Duplicate Records | B4: All columns | C4: 0 | D4: No duplicate records found
A5: Insconsistent Formatting | B5: Gender | C5: 0 | D5: No inconsistency found
A6: Inconsistent Formatting | B6: City | C6: 0 | D6: No inconsistency found
A7: Inconsistent Formatting | B7: Product | C7: 0 | D7: No inconsistency found
A8: Inconsistent Formatting | B8: Category | C8: 0 | D8: No inconsistency found
A9: Inconsistent Formatting | B9: Order_Date | C9: 0 | D9: No inconsistency found
A10: Inconsistent Formatting | B10: Order_ID | C10: 0 | D10: No inconsistency found
A11: Inconsistent Formatting | B11: Customer_ID | C11: 0 | D11: No inconsistency found
A12: Inconsistent Formatting | B12: Customer_Name | C12: 0 | D12: No inconsistency found
A13: Outliers | B13: Age | C13: 0 | D13: No outliers found
... A16: Outliers | B16: Total_Sales | C16: 19 | D16: Review extreme sales values and verify against source data

Sheet Data_Dictionary
A1: Colums Items | B1: Description | C1: Data type | D1: Business relevance
A2: Order_ID | B2: Unique ID assigned to each order | C2: Text | D2: Used to uniquely identify and track each order
A3: Order_Date | B3: Date when the order was placed | C3: Date | D3: Used to analyze sales trends over different dates, days, months, or periods
A4: Customer_ID | B4: Unique ID assigned to each customer | C4: Text | D4: Used to identify customers and analyze their purchasing behavior
A5: Customer_Name | B5: Name of the customer | C5: Text | D5: Used to identify customers and connect orders to customer information
A6: Age | B6: Age of the customer | C6: Integer | D6: Used to understand customer demographics and analyze purchasing behavior by age group
A7: Gender | B7: Gender of the customer | C7: Text | D7: Used to analyze customer demographics and compare purchasing patterns
A8: City | B8: City where the customer is located | C8: Text | D8: Used to analyze sales and customer distribution by location
A9: Product | B9: Product purchased by the customer | C9: Text | D9: Used to identify which products are being purchased and measure product performance
A10: Category | B10: Category of the purchased product | C10: Text | D10: Used to compare sales performance across different product categories
A11: Quantity | B11: Number of items purchased | C11: Integer | D11: Used to measure the number of products sold and analyze sales volume
A12: Unit_Price | B12: Price of one unit of the product | C12: Decimal | D12: Used to analyze product pricing and calculate sales value
A13: Total_Sales | B13: Total value of the order | C13: Decimal | D13: Used to measure revenue and analyze overall sales performance

Sheet Sheet9

Sheet Sheet10

Sheet Sheet1
A3: Row Labels | B3: Sum of Total_Sales
A4: 2025-01-01 | B4: 23787.6
A5: 2025-01-04 | B5: 307641.35
A6: 2025-01-05 | B6: 194749.86
A7: 2025-01-06 | B7: 721080.92
A8: 2025-01-07 | B8: 591822.16
A9: 2025-01-08 | B9: 72852.1
A10: 2025-01-09 | B10: 539901.84
A11: 2025-01-10 | B11: 625004.75
A12: 2025-01-11 | B12: 853136.58
A13: 2025-01-13 | B13: 296338.06
A14: 2025-01-14 | B14: 696953.82
A15: 2025-01-15 | B15: 509436.29
... A346: Grand Total | B346: 1.3939944e+08

Sheet Cleaned_Sales_Dataset
A1: Order_ID | B1: Order_Date | C1: Customer_ID | D1: Customer_Name | E1: Age | F1: Gender | G1: City | H1: Product | I1: Category | J1: Quantity | K1: Unit_Price | L1: TotalSales
A2: ORD100002 | B2: 2025-02-25 | C2: CUST5529 | D2: Customer_227 | E2: 30 | F2: Female | G2: Bengaluru | H2: Rice | I2: Grocery | J2: 7 | K2: 2829.77 | L2: 19808.39 | N2: =DATEVALUE(LEFT(B2,10)) -> 45713 | O2: =ISNUMBER(N2) -> TRUE
A3: ORD100003 | B3: 2025-10-14 | C3: CUST3127 | D3: Customer_182 | E3: 63 | F3: Male | G3: Bengaluru | H3: Book | I3: Education | J3: 5 | K3: 27906.16 | L3: 139530.8 | N3: =DATEVALUE(LEFT(B3,10)) -> 45944 | O3: =ISNUMBER(N3) -> TRUE
A4: ORD100004 | B4: 2025-05-13 | C4: CUST8887 | D4: Customer_487 | E4: 62 | F4: Female | G4: Bengaluru | H4: Book | I4: Education | J4: 8 | K4: 37491.06 | L4: 299928.48 | N4: =DATEVALUE(LEFT(B4,10)) -> 45790 | O4: =ISNUMBER(N4) -> TRUE
A5: ORD100005 | B5: 2025-12-02 | C5: CUST2515 | D5: Customer_470 | E5: 65 | F5: Female | G5: Kolkata | H5: Mobile | I5: Electronics | J5: 9 | K5: 28541.36 | L5: 256872.24 | N5: =DATEVALUE(LEFT(B5,10)) -> 45993 | O5: =ISNUMBER(N5) -> TRUE
A6: ORD100006 | B6: 2025-11-20 | C6: CUST4796 | D6: Customer_380 | E6: 44 | F6: Male | G6: Bengaluru | H6: Rice | I6: Grocery | J6: 10 | K6: 14036.59 | L6: 140365.9 | N6: =DATEVALUE(LEFT(B6,10)) -> 45981 | O6: =ISNUMBER(N6) -> TRUE
A7: ORD100007 | B7: 2025-12-31 | C7: CUST3952 | D7: Customer_71 | E7: 40 | F7: Female | G7: Hyderabad | H7: Laptop | I7: Electronics | J7: 9 | K7: 35947.47 | L7: 323527.23 | N7: =DATEVALUE(LEFT(B7,10)) -> 46022 | O7: =ISNUMBER(N7) -> TRUE
A8: ORD100008 | B8: 2025-10-14 | C8: CUST1758 | D8: Customer_335 | E8: 61 | F8: Male | G8: Patna | H8: Mobile | I8: Electronics | J8: 6 | K8: 49997.53 | L8: 299985.18 | N8: =DATEVALUE(LEFT(B8,10)) -> 45944 | O8: =ISNUMBER(N8) -> TRUE
A9: ORD100009 | B9: 2025-12-05 | C9: CUST9622 | D9: Customer_224 | E9: 35 | F9: Male | G9: Kolkata | H9: Laptop | I9: Electronics | J9: 3 | K9: 9488.83 | L9: 28466.49 | N9: =DATEVALUE(LEFT(B9,10)) -> 45996 | O9: =ISNUMBER(N9) -> TRUE
A10: ORD100010 | B10: 2025-11-21 | C10: CUST9770 | D10: Customer_494 | E10: 41 | F10: Female | G10: Mumbai | H10: Book | I10: Education | J10: 6 | K10: 19488.23 | L10: 116929.38 | N10: =DATEVALUE(LEFT(B10,10)) -> 45982 | O10: =ISNUMBER(N10) -> TRUE
A11: ORD100011 | B11: 2025-04-16 | C11: CUST1312 | D11: Customer_40 | E11: 30 | F11: Male | G11: Kolkata | H11: Mobile | I11: Electronics | J11: 8 | K11: 18024.34 | L11: 144194.72 | N11: =DATEVALUE(LEFT(B11,10)) -> 45763 | O11: =ISNUMBER(N11) -> TRUE
A12: ORD100012 | B12: 2025-05-05 | C12: CUST9642 | D12: Customer_162 | E12: 51 | F12: Male | G12: Delhi | H12: Shoes | I12: Fashion | J12: 3 | K12: 14151.42 | L12: 42454.26 | N12: =DATEVALUE(LEFT(B12,10)) -> 45782 | O12: =ISNUMBER(N12) -> TRUE
A13: ORD100013 | B13: 2025-05-02 | C13: CUST3228 | D13: Customer_209 | E13: 55 | F13: Female | G13: Patna | H13: Chair | I13: Furniture | J13: 6 | K13: 47175.43 | L13: 283052.58 | N13: =DATEVALUE(LEFT(B13,10)) -> 45779 | O13: =ISNUMBER(N13) -> TRUE
... A28: ORD100028 | B28: 2025-08-01 | C28: CUST2003 | D28: Customer_48 | E28: 35 | F28: Female | G28: Mumbai | H28: Rice | I28: Grocery | J28: 2 | K28: 23837.41 | L28: 47674.82 | N28: =DATEVALUE(LEFT(B28,10)) -> 45870 | O28: =ISNUMBER(N28) -> TRUE
A29: ORD100029 | B29: 2025-08-10 | C29: CUST6149 | D29: Customer_181 | E29: 32 | F29: Female | G29: Patna | H29: Laptop | I29: Electronics | J29: 5 | K29: 14534.79 | L29: 72673.95 | N29: =DATEVALUE(LEFT(B29,10)) -> 45879 | O29: =ISNUMBER(N29) -> TRUE | Q29: clea
A30: ORD100030 | B30: 2025-02-05 | C30: CUST3688 | D30: Customer_205 | E30: 38 | F30: Female | G30: Bengaluru | H30: Mobile | I30: Electronics | J30: 10 | K30: 21393.69 | L30: 213936.9 | N30: =DATEVALUE(LEFT(B30,10)) -> 45693 | O30: =ISNUMBER(N30) -> TRUE
A31: ORD100031 | B31: 2025-08-09 | C31: CUST3212 | D31: Customer_415 | E31: 33 | F31: Male | G31: Gaya | H31: Rice | I31: Grocery | J31: 2 | K31: 21382.16 | L31: 42764.32 | N31: =DATEVALUE(LEFT(B31,10)) -> 45878 | O31: =ISNUMBER(N31) -> TRUE
A32: ORD100032 | B32: 2025-05-13 | C32: CUST5063 | D32: Customer_50 | E32: 33 | F32: Female | G32: Mumbai | H32: Mobile | I32: Electronics | J32: 1 | K32: 15831.03 | L32: 15831.03 | N32: =DATEVALUE(LEFT(B32,10)) -> 45790 | O32: =ISNUMBER(N32) -> TRUE
A33: ORD100033 | B33: 2025-10-22 | C33: CUST9565 | D33: Customer_350 | E33: 21 | F33: Female | G33: Mumbai | H33: Book | I33: Education | J33: 8 | K33: 21791.66 | L33: 174333.28 | N33: =DATEVALUE(LEFT(B33,10)) -> 45952 | O33: =ISNUMBER(N33) -> TRUE
A34: ORD100034 | B34: 2025-12-04 | C34: CUST9325 | D34: Customer_352 | E34: 44 | F34: Female | G34: Mumbai | H34: Laptop | I34: Electronics | J34: 5 | K34: 17556.08 | L34: 87780.4 | N34: =DATEVALUE(LEFT(B34,10)) -> 45995 | O34: =ISNUMBER(N34) -> TRUE
A35: ORD100035 | B35: 2025-05-03 | C35: CUST4002 | D35: Customer_388 | E35: 18 | F35: Female | G35: Gaya | H35: Laptop | I35: Electronics | J35: 5 | K35: 46822.84 | L35: 234114.2 | N35: =DATEVALUE(LEFT(B35,10)) -> 45780 | O35: =ISNUMBER(N35) -> TRUE
A36: ORD100036 | B36: 2025-03-08 | C36: CUST8975 | D36: Customer_315 | E36: 36 | F36: Female | G36: Gaya | H36: Mobile | I36: Electronics | J36: 4 | K36: 47896.7 | L36: 191586.8 | N36: =DATEVALUE(LEFT(B36,10)) -> 45724 | O36: =ISNUMBER(N36) -> TRUE
A37: ORD100037 | B37: 2025-02-07 | C37: CUST2669 | D37: Customer_151 | E37: 46 | F37: Male | G37: Bengaluru | H37: Laptop | I37: Electronics | J37: 8 | K37: 44911.49 | L37: 359291.92 | N37: =DATEVALUE(LEFT(B37,10)) -> 45695 | O37: =ISNUMBER(N37) -> TRUE
A38: ORD100038 | B38: 2025-02-20 | C38: CUST5869 | D38: Customer_415 | E38: 23 | F38: Male | G38: Delhi | H38: Chair | I38: Furniture | J38: 7 | K38: 40746.79 | L38: 285227.53 | N38: =DATEVALUE(LEFT(B38,10)) -> 45708 | O38: =ISNUMBER(N38) -> TRUE
A39: ORD100039 | B39: 2025-10-20 | C39: CUST7249 | D39: Customer_144 | E39: 29 | F39: Male | G39: Kolkata | H39: Rice | I39: Grocery | J39: 4 | K39: 4794.08 | L39: 19176.32 | N39: =DATEVALUE(LEFT(B39,10)) -> 45950 | O39: =ISNUMBER(N39) -> TRUE
A40: ORD100040 | B40: 2025-03-07 | C40: CUST7465 | D40: Customer_345 | E40: 58 | F40: Female | G40: Bengaluru | H40: Shoes | I40: Fashion | J40: 8 | K40: 29270.98 | L40: 234167.84 | N40: =DATEVALUE(LEFT(B40,10)) -> 45723 | O40: =ISNUMBER(N40) -> TRUE
A41: ORD100041 | B41: 2025-04-21 | C41: CUST7988 | D41: Customer_383 | E41: 39 | F41: Female | G41: Mumbai | H41: Shoes | I41: Fashion | J41: 1 | K41: 3992.85 | L41: 3992.85 | N41: =DATEVALUE(LEFT(B41,10)) -> 45768 | O41: =ISNUMBER(N41) -> TRUE
... A49: ORD100049 | B49: 2025-10-25 | C49: CUST2705 | D49: Customer_117 | E49: 55 | F49: Male | G49: Kolkata | H49: Mobile | I49: Electronics | J49: 5 | K49: 24854.05 | L49: 124270.25 | N49: =DATEVALUE(LEFT(B49,10)) -> 45955 | O49: =ISNUMBER(N49) -> TRUE
A50: ORD100050 | B50: 2025-10-03 | C50: CUST5523 | D50: Customer_432 | F50: Male | G50: Pune | H50: Chair | I50: Furniture | J50: 9 | K50: 30834.87 | L50: 277513.83 | N50: =DATEVALUE(LEFT(B50,10)) -> 45933 | O50: =ISNUMBER(N50) -> TRUE
A51: ORD100051 | B51: 2025-02-27 | C51: CUST1557 | D51: Customer_87 | E51: 39 | F51: Female | G51: Mumbai | H51: Chair | I51: Furniture | J51: 6 | K51: 20561.97 | L51: 123371.82 | N51: =DATEVALUE(LEFT(B51,10)) -> 45715 | O51: =ISNUMBER(N51) -> TRUE
A52: ORD100052 | B52: 2025-09-09 | C52: CUST2062 | D52: Customer_254 | E52: 58 | F52: Male | G52: Patna | H52: Book | I52: Education | J52: 10 | K52: 49367.75 | L52: 493677.5 | N52: =DATEVALUE(LEFT(B52,10)) -> 45909 | O52: =ISNUMBER(N52) -> TRUE
A53: ORD100053 | B53: 2025-06-08 | C53: CUST9203 | D53: Customer_70 | E53: 33 | F53: Male | G53: Delhi | H53: Laptop | I53: Electronics | J53: 6 | K53: 4656.1 | L53: 27936.6 | N53: =DATEVALUE(LEFT(B53,10)) -> 45816 | O53: =ISNUMBER(N53) -> TRUE
A54: ORD100054 | B54: 2025-07-07 | C54: CUST8053 | D54: Customer_408 | E54: 58 | F54: Male | G54: Delhi | H54: Rice | I54: Grocery | J54: 7 | K54: 42345.82 | L54: 296420.74 | N54: =DATEVALUE(LEFT(B54,10)) -> 45845 | O54: =ISNUMBER(N54) -> TRUE
A55: ORD100055 | B55: 2025-04-16 | C55: CUST1017 | D55: Customer_387 | E55: 42 | F55: Female | G55: Pune | H55: Shoes | I55: Fashion | J55: 7 | K55: 37747.24 | L55: 264230.68 | N55: =DATEVALUE(LEFT(B55,10)) -> 45763 | O55: =ISNUMBER(N55) -> TRUE
A56: ORD100056 | B56: 2025-11-16 | C56: CUST2690 | D56: Customer_11 | E56: 26 | F56: Male | G56: Delhi | H56: Book | I56: Education | J56: 2 | K56: 33304.17 | L56: 66608.34 | N56: =DATEVALUE(LEFT(B56,10)) -> 45977 | O56: =ISNUMBER(N56) -> TRUE
A57: ORD100057 | B57: 2025-12-07 | C57: CUST2791 | D57: Customer_20 | E57: 58 | F57: Female | G57: Bengaluru | H57: Laptop | I57: Electronics | J57: 6 | K57: 41157.44 | L57: 246944.64 | N57: =DATEVALUE(LEFT(B57,10)) -> 45998 | O57: =ISNUMBER(N57) -> TRUE
A58: ORD100058 | B58: 2025-03-12 | C58: CUST4496 | D58: Customer_53 | E58: 18 | F58: Female | G58: Bengaluru | H58: Chair | I58: Furniture | J58: 7 | K58: 47669.63 | L58: 333687.41 | N58: =DATEVALUE(LEFT(B58,10)) -> 45728 | O58: =ISNUMBER(N58) -> TRUE
A59: ORD100059 | B59: 2025-12-12 | C59: CUST8811 | D59: Customer_115 | E59: 50 | F59: Female | G59: Bengaluru | H59: Chair | I59: Furniture | J59: 1 | K59: 44708.5 | L59: 44708.5 | N59: =DATEVALUE(LEFT(B59,10)) -> 46003 | O59: =ISNUMBER(N59) -> TRUE
A60: ORD100060 | B60: 2025-01-15 | C60: CUST2411 | D60: Customer_292 | E60: 47 | F60: Female | G60: Mumbai | H60: Mobile | I60: Electronics | J60: 5 | K60: 36809.08 | L60: 184045.4 | N60: =DATEVALUE(LEFT(B60,10)) -> 45672 | O60: =ISNUMBER(N60) -> TRUE
A61: ORD100061 | B61: 2025-11-08 | C61: CUST2350 | D61: Customer_205 | E61: 46 | F61: Male | G61: Pune | H61: Mobile | I61: Electronics | J61: 4 | K61: 25292.97 | L61: 101171.88 | N61: =DATEVALUE(LEFT(B61,10)) -> 45969 | O61: =ISNUMBER(N61) -> TRUE
...

Sheet Numerical_Analysis
A1: Numerical Column | B1: Count | C1: Mean | D1: Median | E1: Mode | F1: Minimum | G1: Maximum | H1: Standard Deviation | I1: Q1 | J1: Q3 | K1: IQR
A2: Age | B2: =COUNT(Cleaned_Sales_Dataset!E2:E1001) -> 980 | C2: =AVERAGE(Cleaned_Sales_Dataset!E2:E1001) -> 41.360204 | D2: =MEDIAN(Cleaned_Sales_Dataset!E2:E1001) -> 41 | E2: =_xlfn.MODE.SNGL(Cleaned_Sales_Dataset!E2:E1001) -> 30 | F2: =MIN(Cleaned_Sales_Dataset!E2:E1001) -> 18 | G2: =MAX(Cleaned_Sales_Dataset!E2:E1001) -> 65 | H2: =_xlfn.STDEV.S(Cleaned_Sales_Dataset!E2:E1001) -> 13.822597 | I2: =_xlfn.QUARTILE.INC(Cleaned_Sales_Dataset!E2:E1001,1) -> 30 | J2: =_xlfn.QUARTILE.INC(Cleaned_Sales_Dataset!E2:E1001,3) -> 54 | K2: =J2-I2 -> 24
A3: Quantity | B3: =COUNT(Cleaned_Sales_Dataset!J2:J1001) -> 1000 | C3: =AVERAGE(Cleaned_Sales_Dataset!J2:J1002) -> 5.435 | D3: =MEDIAN(Cleaned_Sales_Dataset!J2:J1001) -> 5 | E3: =_xlfn.MODE.SNGL(Cleaned_Sales_Dataset!J2:J1001) -> 5 | F3: =MIN(Cleaned_Sales_Dataset!J2:J1001) -> 1 | G3: =MAX(Cleaned_Sales_Dataset!J2:J1001) -> 10 | H3: =_xlfn.STDEV.S(Cleaned_Sales_Dataset!J2:J1001) -> 2.8386322 | I3: =_xlfn.QUARTILE.INC(Cleaned_Sales_Dataset!J2:J1001,1) -> 3 | J3: =_xlfn.QUARTILE.INC(Cleaned_Sales_Dataset!J2:J1001,3) -> 8 | K3: =J3-I3 -> 5
A4: Unit_Price | B4: =COUNT(Cleaned_Sales_Dataset!K2:K1001) -> 1000 | C4: =AVERAGE(Cleaned_Sales_Dataset!K2:K1001) -> 25486.783 | D4: =MEDIAN(Cleaned_Sales_Dataset!K2:K1001) -> 25398.74 | E4: 3 | F4: =MIN(Cleaned_Sales_Dataset!K2:K1001) -> 145.78 | G4: =MAX(Cleaned_Sales_Dataset!K2:K1001) -> 49997.53 | H4: =_xlfn.STDEV.S(Cleaned_Sales_Dataset!K2:K1001) -> 14179.402 | I4: =_xlfn.QUARTILE.INC(Cleaned_Sales_Dataset!K2:K1001,1) -> 13895.722 | J4: =_xlfn.QUARTILE.INC(Cleaned_Sales_Dataset!K2:K1001,3) -> 37512.382 | K4: =J4-I4 -> 23616.66
A5: Total_Sales | B5: =COUNT(Cleaned_Sales_Dataset!L2:L1001) -> 1000 | C5: =AVERAGE(Cleaned_Sales_Dataset!L2:L1001) -> 139399.44 | D5: =MEDIAN(Cleaned_Sales_Dataset!L2:L1001) -> 108594.02 | E5: 3 | F5: =MIN(Cleaned_Sales_Dataset!L2:L1001) -> 437.34 | G5: =MAX(Cleaned_Sales_Dataset!L2:L1001) -> 493677.5 | H5: =_xlfn.STDEV.S(Cleaned_Sales_Dataset!L2:L1001) -> 114100.05 | I5: =_xlfn.QUARTILE.INC(Cleaned_Sales_Dataset!L2:L1001,1) -> 47066.632 | J5: =_xlfn.QUARTILE.INC(Cleaned_Sales_Dataset!L2:L1001,3) -> 203722.88 | K5: =J5-I5 -> 156656.25

Sheet Univariate_Analysis

Sheet Categorical_Analysis
A1: Gender | B1: Count | M1: City | N1: Count
A2: Male | B2: 511 | M2: Bengaluru | N2: 122
A3: Female | B3: 489 | M3: Kolkata | N3: 133
M4: Hyderbad | N4: 125
M5: Patna | N5: 135
M6: Mumbai | N6: 131
M7: Delhi | N7: 125
M8: Gaya | N8: 117
M9: Pune | N9: 99
A20: Category | B20: Count | M20: Product | N20: Count
A21: Grocery | B21: 153 | M21: Rice | N21: 153
A22: Education | B22: 178 | M22: Book | N22: 178
A23: Electronics | B23: 354 | M23: Mobile | N23: 184
A24: Fashion | B24: 156 | M24: Laptop | N24: 170
A25: Furniture | B25: 159 | M25: Shoes | N25: 156
M26: Chair | N26: 159

Sheet KPI_Calculations
A1: A | B1: B
A2: KPI | B2: Value
A3: Total Revenue
A4: Total Orders | B4: =COUNTA(Cleaned_Sales_Dataset!A:A)-1 -> 1000 | E4: SALES & CUSTOMER ANALYTICS DASHBOARD
A5: Total Quantity Sold
A6: Average Order Value | E6: TOTAL REVENUE | G6: TOTAL ORDERS | I6: QUANTITY SOLD
A7: Total Customers | B7: =SUMPRODUCT((Cleaned_Sales_Dataset!C2:C1001<>"")/COUNTIF(Cleaned_Sales_Dataset!C2:C1001,Cleaned_Sales_Dataset!C2:C1001&"")) -> 947 | E7: =KPI_Calculations!F6 -> 0 | G7: =KPI_Calculations!F7 -> 0 | I7: =KPI_Calculations!F8 -> 0
A8: Total Cities
E9: AVG ORDER VALUE | G9: TOTAL CUSTOMERS | I9: TOTAL CITIES
E10: =KPI_Calculations!F9 -> 0 | G10: =KPI_Calculations!F10 -> 0 | I10: =KPI_Calculations!F11 -> 0

Sheet Dashboard
L1: A | M1: B
A2: SALES & CUSTOMER ANALYTICS DASHBOARD | L2: KPI | M2: Value
A3: TOTAL REVENUE | C3: TOTAL ORDERS | E3: QUANTITY SOLD | L3: Total Revenue | M3: =SUM(Cleaned_Sales_Dataset!L:L) -> 1.3939944e+08
A4: 139399439 | C4: 1000 | E4: 5435 | L4: Total Orders | M4: =COUNTA(Cleaned_Sales_Dataset!L:L)-1 -> 1000
L5: Total Quantity Sold | M5: =SUM(Cleaned_Sales_Dataset!J:J) -> 5435
A6: AVG ORDER VALUE | C6: TOTAL CUSTOMERS | E6: TOTAL CITIES | L6: Average Order Value | M6: =AVERAGE(Cleaned_Sales_Dataset!L:L) -> 139399.44
A7: 139399.44 | C7: 947 | E7: 8 | L7: Total Customers | M7: =SUMPRODUCT((Cleaned_Sales_Dataset!C2:C1001<>"")/COUNTIF(Cleaned_Sales_Dataset!C2:C1001,Cleaned_Sales_Dataset!C2:C1001&"")) -> 947
L8: Total Cities | M8: =SUMPRODUCT((Cleaned_Sales_Dataset!G2:G1001<>"")/COUNTIF(Cleaned_Sales_Dataset!G2:G1001,Cleaned_Sales_Dataset!G2:G1001&"")) -> 8

Sheet Multivariate Analysis 
D34: Correlation Heatmap
C35: Age | D35: Quantity | E35: Unit Price | F35: Total Sales
B36: Age | C36: =CORREL(Cleaned_Sales_Dataset!E2:E1001,Cleaned_Sales_Dataset!E2:E1001) -> 1 | D36: =CORREL(Cleaned_Sales_Dataset!E2:E1001,Cleaned_Sales_Dataset!J2:J1001) -> -0.027627814 | E36: =CORREL(Cleaned_Sales_Dataset!E2:E1001,Cleaned_Sales_Dataset!K2:K1001) -> -0.012213721 | F36: =CORREL(Cleaned_Sales_Dataset!E2:E1001,Cleaned_Sales_Dataset!L2:L1001) -> 0.0014789938
B37: Quantity | C37: =CORREL(Cleaned_Sales_Dataset!E2:E1001,Cleaned_Sales_Dataset!K2:K1001) -> -0.012213721 | D37: =CORREL(Cleaned_Sales_Dataset!J2:J1001,Cleaned_Sales_Dataset!J2:J1001) -> 1 | E37: =CORREL(Cleaned_Sales_Dataset!L2:L1001,Cleaned_Sales_Dataset!K2:K1001) -> 0.68630343 | F37: =CORREL(Cleaned_Sales_Dataset!J2:J1001,Cleaned_Sales_Dataset!L2:L1001) -> 0.64664062
B38: Unit Price | C38: =CORREL(Cleaned_Sales_Dataset!J2:J1001,Cleaned_Sales_Dataset!E2:E1001) -> -0.027627814 | D38: =CORREL(Cleaned_Sales_Dataset!K2:K1001,Cleaned_Sales_Dataset!J2:J1001) -> 0.021854636 | E38: =CORREL(Cleaned_Sales_Dataset!K2:K1001,Cleaned_Sales_Dataset!K2:K1001) -> 1 | F38: =CORREL(Cleaned_Sales_Dataset!K2:K1001,Cleaned_Sales_Dataset!L2:L1001) -> 0.68630343
B39: Total Sales | C39: =CORREL(Cleaned_Sales_Dataset!L2:L1001,Cleaned_Sales_Dataset!E2:E1001) -> 0.0014789938 | D39: =CORREL(Cleaned_Sales_Dataset!L2:L1001,Cleaned_Sales_Dataset!J2:J1001) -> 0.64664062 | E39: =CORREL(Cleaned_Sales_Dataset!L2:L1001,Cleaned_Sales_Dataset!K2:K1001) -> 0.68630343 | F39: =CORREL(Cleaned_Sales_Dataset!L2:L1001,Cleaned_Sales_Dataset!L2:L1001) -> 1
C41: Key Business Insights
C42: Realtionship | F42: Corrrelation | G42: Interpreation
C43: Unit Price VS Total Sales | F43: 0.686 | G43: Strong Postive Realtionship
C44: Quantity VS Total Sales | F44: 0.647 | G44: Moderate-to-Strong Postive Relationship
C45: Age VS Total Sales | F45: 0.001 | G45: Almost no Realtionship
C46: Quantity VS Unit Price | F46: 0.022 | G46: Almost no Realtionship
